#!/usr/bin/env python3
"""
TASK-502: エラーリカバリ実装 - テストコード（Red Phase）

ErrorRecoveryManagerと各種リカバリハンドラーのテストスイート。
Priority 1の必須テストを実装。
"""

import unittest
from unittest.mock import Mock, MagicMock, patch, call
import tempfile
import json
import os
from typing import Dict, Any
import time

# まだ実装されていないがテスト対象のクラス
try:
    from src.core.error_recovery import (
        ErrorRecoveryManager,
        NetworkRecoveryHandler,
        FileSystemRecoveryHandler,
        MemoryRecoveryHandler
    )
except ImportError:
    # Red Phaseではクラスが存在しないのでダミー定義
    class ErrorRecoveryManager:
        def __init__(self, settings: Dict[str, Any]):
            pass
        
        def register_handler(self, error_type, handler):
            pass
        
        def wrap_with_recovery(self, func):
            return func
        
        def handle_error(self, error, context=None):
            return False
        
        def get_recovery_stats(self):
            return {}
    
    class NetworkRecoveryHandler:
        def __init__(self, max_retries=5, backoff_factor=2.0):
            pass
        
        def handle_network_error(self, error, retry_count):
            return False
        
        def get_retry_delay(self, retry_count):
            return 0
    
    class FileSystemRecoveryHandler:
        def __init__(self, fallback_paths=None):
            pass
        
        def handle_file_error(self, error, file_path):
            return None
        
        def repair_corrupted_file(self, file_path):
            return False
    
    class MemoryRecoveryHandler:
        def __init__(self, threshold=200):
            pass
        
        def handle_memory_error(self, error):
            return False
        
        def clear_caches(self):
            return 0
        
        def reduce_quality_settings(self):
            return {}


class TestErrorRecoveryManager(unittest.TestCase):
    """ErrorRecoveryManagerの基本機能テスト"""
    
    def setUp(self):
        """各テストの前処理"""
        self.test_settings = {
            'error_recovery': {
                'enabled': True,
                'network': {
                    'max_retries': 5,
                    'backoff_factor': 2.0,
                    'initial_delay': 1.0
                },
                'filesystem': {
                    'fallback_paths': ['/tmp/test1', '/tmp/test2'],
                    'auto_repair': True
                },
                'memory': {
                    'threshold_mb': 200,
                    'auto_clear_cache': True
                }
            }
        }
    
    def test_manager_initialization(self):
        """Test 1.1: マネージャー初期化"""
        manager = ErrorRecoveryManager(self.test_settings)
        
        # インスタンスが作成されることを確認
        self.assertIsNotNone(manager)
        
        # 設定が保持されることを確認（実装後にテスト）
        # self.assertEqual(manager.enabled, True)
    
    def test_error_handler_registration(self):
        """Test 1.2: エラーハンドラー登録"""
        manager = ErrorRecoveryManager(self.test_settings)
        
        # モックハンドラー
        mock_handler = Mock(return_value=True)
        
        # ハンドラー登録
        manager.register_handler(ConnectionError, mock_handler)
        
        # エラー処理（実装後は登録したハンドラーが呼ばれるはず）
        result = manager.handle_error(ConnectionError("Test error"))
        
        # 現時点では False が返る（未実装）
        self.assertFalse(result)
    
    def test_function_wrapping(self):
        """Test 1.3: 関数ラッピング"""
        manager = ErrorRecoveryManager(self.test_settings)
        
        # テスト用関数
        def test_func():
            raise ValueError("Test error")
        
        # ラップ
        wrapped_func = manager.wrap_with_recovery(test_func)
        
        # エラーが発生してもクラッシュしないことを確認
        # （未実装なので現時点では例外が発生する）
        with self.assertRaises(ValueError):
            wrapped_func()


class TestNetworkRecoveryHandler(unittest.TestCase):
    """NetworkRecoveryHandlerのテスト"""
    
    def setUp(self):
        """各テストの前処理"""
        self.handler = NetworkRecoveryHandler(max_retries=5, backoff_factor=2.0)
    
    def test_network_error_handling(self):
        """Test 2.1: ネットワークエラーハンドリング"""
        import requests
        
        # ConnectionErrorの処理
        error = requests.exceptions.ConnectionError("Connection failed")
        
        # 1回目の再試行は許可されるべき
        result = self.handler.handle_network_error(error, retry_count=0)
        self.assertTrue(result)
        
        # 5回目までは再試行を許可
        result = self.handler.handle_network_error(error, retry_count=4)
        self.assertTrue(result)
        
        # 6回目は許可しない
        result = self.handler.handle_network_error(error, retry_count=5)
        self.assertFalse(result)
    
    def test_exponential_backoff(self):
        """Test 2.2: 指数バックオフ計算"""
        # 再試行間隔の計算
        delays = [
            self.handler.get_retry_delay(0),  # 1秒期待
            self.handler.get_retry_delay(1),  # 2秒期待
            self.handler.get_retry_delay(2),  # 4秒期待
            self.handler.get_retry_delay(3),  # 8秒期待
        ]
        
        # 実装された期待値
        self.assertEqual(delays, [1.0, 2.0, 4.0, 8.0])


class TestFileSystemRecoveryHandler(unittest.TestCase):
    """FileSystemRecoveryHandlerのテスト"""
    
    def setUp(self):
        """各テストの前処理"""
        self.fallback_paths = ['/tmp/fallback1', '/tmp/fallback2']
        self.handler = FileSystemRecoveryHandler(fallback_paths=self.fallback_paths)
        
        # テスト用の一時ファイル
        self.temp_file = tempfile.NamedTemporaryFile(mode='w', delete=False, suffix='.json')
        self.temp_file.close()
    
    def tearDown(self):
        """各テストの後処理"""
        # 一時ファイルのクリーンアップ
        if os.path.exists(self.temp_file.name):
            os.unlink(self.temp_file.name)
    
    def test_file_error_handling(self):
        """Test 3.1: ファイルエラーハンドリング"""
        # PermissionErrorの処理
        error = PermissionError("Permission denied")
        
        # 代替パスを返すべき
        result = self.handler.handle_file_error(error, "/original/path/file.txt")
        
        # 未実装なのでNone
        self.assertIsNone(result)
        
        # 実装後は代替パスが返されるはず
        # self.assertIn(result, self.fallback_paths)
    
    def test_corrupted_file_repair(self):
        """Test 3.2: 破損ファイル修復"""
        # 破損したJSONファイルを作成
        with open(self.temp_file.name, 'w') as f:
            f.write("{ invalid json }")
        
        # 修復試行
        result = self.handler.repair_corrupted_file(self.temp_file.name)
        
        # 実装後はファイルが削除されてTrueが返る
        self.assertTrue(result)
        self.assertFalse(os.path.exists(self.temp_file.name))


class TestMemoryRecoveryHandler(unittest.TestCase):
    """MemoryRecoveryHandlerのテスト"""
    
    def setUp(self):
        """各テストの前処理"""
        self.handler = MemoryRecoveryHandler(threshold=200)
    
    def test_memory_error_handling(self):
        """Test 4.1: メモリエラーハンドリング"""
        # MemoryErrorの処理
        error = MemoryError("Out of memory")
        
        # キャッシュクリアを実行すべき
        result = self.handler.handle_memory_error(error)
        
        # 実装後はTrueが返る
        self.assertTrue(result)
    
    def test_cache_clearing(self):
        """Test 4.2: キャッシュクリア"""
        # キャッシュクリア実行
        freed_bytes = self.handler.clear_caches()
        
        # 実装後は解放されたバイト数が返る
        self.assertGreater(freed_bytes, 0)


class TestIntegration(unittest.TestCase):
    """統合テスト"""
    
    def setUp(self):
        """各テストの前処理"""
        self.settings = {
            'error_recovery': {
                'enabled': True,
                'network': {'max_retries': 3, 'backoff_factor': 2.0},
                'filesystem': {'fallback_paths': ['/tmp/test']},
                'memory': {'threshold_mb': 100}
            }
        }
        self.manager = ErrorRecoveryManager(self.settings)
    
    def test_multiple_error_handling(self):
        """Test 5.1: 複数エラーの同時処理"""
        import requests
        
        # 異なるエラータイプ
        network_error = requests.exceptions.ConnectionError("Network error")
        file_error = PermissionError("File error")
        
        # 両方のエラーを処理
        result1 = self.manager.handle_error(network_error)
        result2 = self.manager.handle_error(file_error)
        
        # ネットワークエラーは処理成功、ファイルエラーは代替パス不在で失敗の場合がある
        self.assertTrue(result1)  # ネットワークエラーは再試行可能
        # result2はファイルシステムの状態に依存
    
    def test_recovery_statistics(self):
        """Test 5.2: リカバリ統計収集"""
        # 複数のエラーを処理
        for i in range(5):
            self.manager.handle_error(ValueError(f"Error {i}"))
        
        # 統計を取得
        stats = self.manager.get_recovery_stats()
        
        # 実装後は統計情報が含まれる
        self.assertIn('total_errors', stats)
        self.assertEqual(stats['total_errors'], 5)
        self.assertIn('error_types', stats)
        self.assertEqual(stats['error_types']['ValueError'], 5)


if __name__ == '__main__':
    unittest.main()